<?xml version="1.0"?>
<robot xmlns:xacro="http://www.ros.org/wiki/xacro" name="robot">
  <xacro:include filename="inertia_xacro"/>



<material name="white">
    <color rgba="1 1 1 1"/>
</material>

<material name="orange">
    <color rgba="1 0.3 0.1 1"/>
</material>

<material name="blue">
    <color rgba="0.2 0.2 1 1"/>
</material>

<material name="black">
    <color rgba="0 0 0 1"/>
</material>

<link name="base_link">
</link>

<joint name="chassis_joint" type="fixed">
    <parent link="base_link"/>
    <child link="chassis"/>
    <origin xyz="-0.1 0 0"/>
</joint>

<link name="chassis">
    <visual>
        <origin xyz="0.15 0 0.075"/>
        <geometry>
            <box size="0.3 0.3 0.15"/>
        </geometry>
        <material name="white"/>
    </visual>
    <collision>
        <origin xyz="0.15 0 0.075" rpy="0 0 0"/>
        <geometry>
            <box size="0.3 0.3 0.15"/>
        </geometry>
    </collision>
    <xacro:inertial_box mass="0.5" x="0.3" y="0.3" z="0.15">
        <origin xyz="0.15 0 0.075" rpy="0 0 0"/>
    </xacro:inertial_box>
</link>

<gazebo reference="chassis">
  <material>Gazebo/White</material>
</gazebo>

<!-- LEFT WHEEL -->

<joint name="left_wheel_joint" type="continuous">
    <parent link="base_link"/>
    <child link="left_wheel"/>
    <origin xyz="0 0.175 0" rpy="-${pi/2} 0 0"/>
    <axis xyz="0 0 1"/>
 
</joint>

<link name="left_wheel">
    <visual>
        <geometry>
            <cylinder length="0.04" radius="0.05" />
        </geometry>
        <material name="blue"/>
    </visual>
    <collision>
        <geometry>
            <cylinder length="0.04" radius="0.05" />
        </geometry>
    </collision>
    <xacro:inertial_cylinder mass="0.1" length="0.04" radius="0.05">
        <origin xyz="0 0 0" rpy="0 0 0"/>
    </xacro:inertial_cylinder>
</link>
<gazebo reference="left_wheel">
  <material>Gazebo/Blue</material>
</gazebo>

<!-- RIGHT WHEEL -->

<joint name="right_wheel_joint" type="continuous">
    <parent link="base_link"/>
    <child link="right_wheel"/>
    <origin xyz="0 -0.175 0" rpy="${pi/2} 0 0"/>
    <axis xyz="0 0 -1"/>
</joint>

<link name="right_wheel">
    <visual>
        <geometry>
            <cylinder length="0.04" radius="0.05" />
        </geometry>
        <material name="blue"/>
    </visual>
    <collision>
        <geometry>
            <cylinder length="0.04" radius="0.05" />
        </geometry>
    </collision>
    <xacro:inertial_cylinder mass="0.1" length="0.04" radius="0.05">
        <origin xyz="0 0 0" rpy="0 0 0"/>
    </xacro:inertial_cylinder>
</link>
<gazebo reference="right_wheel">
  <material>Gazebo/Blue</material>
</gazebo>

<!-- CASTER WHEEL -->

<joint name="caster_wheel_joint" type="fixed">
    <parent link="chassis"/>
    <child link="caster_wheel"/>
    <origin xyz="0.24 0 0"/>
</joint>

<link name="caster_wheel">
    <visual>
        <geometry>
            <sphere radius="0.05" />
        </geometry>
        <material name="black"/>
    </visual>
    <xacro:inertial_sphere mass="0.1" radius="0.05">
        <origin xyz="0 0 0" rpy="0 0 0"/>
    </xacro:inertial_sphere>
</link>
<gazebo reference="caster_wheel">
  <material>Gazebo/Black</material>
  <mu1 value="0.001"/>
  <mu2 value="0.001"/>
</gazebo>
</robot>
  <!-- Base Link 
  <link name="base_link">  
    </link>

<joint name="chassis_link" type="fixed">
 <parent link="base_link"/>
 <child link="chassis"/>
 <origin xyz="0.1 0 0" rpy="0 0 0"/>
  </joint>

<link name ="chassis">  
      <visual>
      <origin xyz = "0 0 0.062"/>
      <geometry>
        <box size="0.300 0.230 0.124"/>
      </geometry>
      <material name="grey">
        <color rgba="0.5 0.5 0.5 1.0"/>
      </material>
    </visual>
    <collision>
    <origin xyz = "0 0 0.062"/>
      <geometry>
        <box size="0.300 0.230 0.124"/>
      </geometry>
    </collision>
    <xacro:inertial_box mass="1.5" x="0.300" y="0.230" z="0.124">
        <origin xyz="0 0 0.062" rpy="0 0 0"/>
    </xacro:inertial_box>
    </link>
    <gazebo reference="chassis">
        <material>Gazebo/lightblue</material>
    </gazebo>

  <! Left Wheel 
  <link name="left_wheel">
    <visual>
      <geometry>
        <cylinder radius="0.0275" length="0.02"/>
      </geometry>
      
      <material name="black">
        <color rgba="0 0 0 1.0"/>
      </material>
    </visual>
    <collision>
      <geometry>
        <cylinder radius="0.0275" length="0.02"/>
      </geometry>
    </collision>
    <xacro:inertial_cylinder mass="0.05" length="0.02" radius="0.0275">
        <origin xyz="0 0 0" rpy="0 0 0"/>
    </xacro:inertial_cylinder>
  </link>
   <gazebo reference="left_wheel">
        <material>Gazebo/white</material>
    </gazebo>

    <! Left Wheel1 
  <link name="left_wheel1">
    <visual>
      <geometry>
        <cylinder radius="0.02" length="0.01"/>
      </geometry>
      
      <material name="black">
        <color rgba="0 0 0 1.0"/>
      </material>
    </visual>
    <collision>
      <geometry>
        <cylinder radius="0.02" length="0.01"/>
      </geometry>
    </collision>
    <xacro:inertial_cylinder mass="0.01" length="0.01" radius="0.02">
        <origin xyz="0 0 0" rpy="0 0 0"/>
    </xacro:inertial_cylinder>
    
  </link>
  <gazebo reference="left_wheel1">
        <material>Gazebo/black</material>
    </gazebo>

    <! Left Wheel2 
  <link name="left_wheel2">
    <visual>
      <geometry>
        <cylinder radius="0.02" length="0.01"/>
      </geometry>
      
      <material name="black">
        <color rgba="0 0 0 1.0"/>
      </material>
    </visual>
    <collision>
      <geometry>
        <cylinder radius="0.02" length="0.01"/>
      </geometry>
    </collision>
    <xacro:inertial_cylinder mass="0.01" length="0.01" radius="0.02">
        <origin xyz="0 0 0" rpy="0 0 0"/>
    </xacro:inertial_cylinder>
  </link>
  <gazebo reference="left_wheel2">
        <material>Gazebo/black</material>
    </gazebo>
    
  <link name="left_wheel3">
    <visual>
      <geometry>
        <cylinder radius="0.02" length="0.01"/>
      </geometry>
      
      <material name="black">
        <color rgba="0 0 0 1.0"/>
      </material>
    </visual>
    <collision>
      <geometry>
        <cylinder radius="0.02" length="0.01"/>
      </geometry>
    </collision>
    <xacro:inertial_cylinder mass="0.01" length="0.01" radius="0.02">
        <origin xyz="0 0 0" rpy="0 0 0"/>
    </xacro:inertial_cylinder>
  </link>
  <gazebo reference="left_wheel3">
        <material>Gazebo/black</material>
    </gazebo>
    
  <link name="left_wheel4">
    <visual>
      <geometry>
        <cylinder radius="0.02" length="0.01"/>
      </geometry>
      
      <material name="black">
        <color rgba="0 0 0 1.0"/>
      </material>
    </visual>
    <collision>
      <geometry>
        <cylinder radius="0.02" length="0.01"/>
      </geometry>
    </collision>
    <xacro:inertial_cylinder mass="0.01" length="0.01" radius="0.02">
        <origin xyz="0 0 0" rpy="0 0 0"/>
    </xacro:inertial_cylinder>
  </link>
  <gazebo reference="left_wheel4">
        <material>Gazebo/black</material>
    </gazebo>

    
  <link name="left_wheel5">
    <visual>
      <geometry>
        <cylinder radius="0.02" length="0.01"/>
      </geometry>
      
      <material name="black">
        <color rgba="0 0 0 1.0"/>
      </material>
    </visual>
    <collision>
      <geometry>
        <cylinder radius="0.02" length="0.01"/>
      </geometry>
    </collision>
    <xacro:inertial_cylinder mass="0.01" length="0.01" radius="0.02">
        <origin xyz="0 0 0" rpy="0 0 0"/>
    </xacro:inertial_cylinder>
  </link>
  <gazebo reference="left_wheel5">
        <material>Gazebo/black</material>
    </gazebo>

 



 
  <link name="right_wheel">
    <visual>
      <geometry>
        <cylinder radius="0.0275" length="0.02"/>
      </geometry>
      <material name="black">
        <color rgba="0 0 0 1.0"/>
      </material>
    </visual>
    <collision>
      <geometry>
        <cylinder radius="0.0275" length="0.02"/>
      </geometry>
    </collision>
        <xacro:inertial_cylinder mass="0.05" length="0.02" radius="0.0275">
        <origin xyz="0 0 0" rpy="0 0 0"/>
    </xacro:inertial_cylinder>
  </link>
  <gazebo reference="right_wheel">
        <material>Gazebo/white</material>
    </gazebo>

    
  <link name="right_wheel1">
    <visual>
      <geometry>
        <cylinder radius="0.02" length="0.01"/>
      </geometry>
      
      <material name="black">
        <color rgba="0 0 0 1.0"/>
      </material>
    </visual>
    <collision>
      <geometry>
        <cylinder radius="0.02" length="0.01"/>
      </geometry>
    </collision>
    <xacro:inertial_cylinder mass="0.01" length="0.01" radius="0.02">
        <origin xyz="0 0 0" rpy="0 0 0"/>
    </xacro:inertial_cylinder>
  </link>
  <gazebo reference="right_wheel1">
        <material>Gazebo/black</material>
    </gazebo>

     
  <link name="right_wheel2">
    <visual>
      <geometry>
        <cylinder radius="0.02" length="0.01"/>
      </geometry>
      
      <material name="black">
        <color rgba="0 0 0 1.0"/>
      </material>
    </visual>
    <collision>
      <geometry>
        <cylinder radius="0.02" length="0.01"/>
      </geometry>
    </collision>
    <xacro:inertial_cylinder mass="0.01" length="0.01" radius="0.02">
        <origin xyz="0 0 0" rpy="0 0 0"/>
    </xacro:inertial_cylinder>
  </link>
  <gazebo reference="right_wheel2">
        <material>Gazebo/black</material>
    </gazebo>

     
  <link name="right_wheel3">
    <visual>
      <geometry>
        <cylinder radius="0.02" length="0.01"/>
      </geometry>
      
      <material name="black">
        <color rgba="0 0 0 1.0"/>
      </material>
    </visual>
    <collision>
      <geometry>
        <cylinder radius="0.02" length="0.01"/>
      </geometry>
    </collision>
    <xacro:inertial_cylinder mass="0.01" length="0.01" radius="0.02">
        <origin xyz="0 0 0" rpy="0 0 0"/>
    </xacro:inertial_cylinder>
  </link>
  <gazebo reference="right_wheel3">
        <material>Gazebo/black</material>
    </gazebo>

   
  <link name="right_wheel4">
    <visual>
      <geometry>
        <cylinder radius="0.02" length="0.01"/>
      </geometry>
      
      <material name="black">
        <color rgba="0 0 0 1.0"/>
      </material>
    </visual>
    <collision>
      <geometry>
        <cylinder radius="0.02" length="0.01"/>
      </geometry>
    </collision>
    <xacro:inertial_cylinder mass="0.01" length="0.01" radius="0.02">
        <origin xyz="0 0 0" rpy="0 0 0"/>
    </xacro:inertial_cylinder>
  </link>
  <gazebo reference="right_wheel4">
        <material>Gazebo/black</material>
    </gazebo>

       
  <link name="right_wheel5">
    <visual>
      <geometry>
        <cylinder radius="0.02" length="0.01"/>
      </geometry>
      
      <material name="black">
        <color rgba="0 0 0 1.0"/>
      </material>
    </visual>
    <collision>
      <geometry>
        <cylinder radius="0.02" length="0.01"/>
      </geometry>
    </collision>
    <xacro:inertial_cylinder mass="0.01" length="0.01" radius="0.02">
        <origin xyz="0 0 0" rpy="0 0 0"/>
    </xacro:inertial_cylinder>
  </link>
  <gazebo reference="right_wheel5">
        <material>Gazebo/black</material>
    </gazebo>


  
  <joint name="left_wheel_joint" type="continuous">
    <parent link="base_link"/>
    <child link="left_wheel"/>
    <origin xyz="-0.013 0.115 0.045" rpy="-1.5708 0 0"/>
    <axis xyz="0 0 1"/>
  </joint>

  
  <joint name="left_wheel_joint_1" type="revolute">
    <parent link="base_link"/>
    <child link="left_wheel1"/>
    <origin xyz="0.110 0.115 0.09" rpy="-1.5708 0 0"/>
    <axis xyz="0 0 1"/>
    <limit lower="0" upper="0" effort="0.0" velocity="0.0"/>
  </joint>
    
  <joint name="left_wheel_joint_2" type="revolute">
    <parent link="base_link"/>
    <child link="left_wheel2"/>
    <origin xyz="0.242 0.115 0.045" rpy="-1.5708 0 0"/>
    <axis xyz="0 0 1"/>
    <limit lower="0" upper="0" effort="0.0" velocity="0.0"/>
  </joint>

      
  <joint name="left_wheel_joint_3" type="revolute">
    <parent link="base_link"/>
    <child link="left_wheel3"/>
    <origin xyz="0.210 0.115 0.01" rpy="-1.5708 0 0"/>
    <axis xyz="0 0 1"/>
    <limit lower="0" upper="0" effort="0.0" velocity="0.0"/>
  </joint>

     
  <joint name="left_wheel_joint_4" type="revolute">
    <parent link="base_link"/>
    <child link="left_wheel4"/>
    <origin xyz="0.130 0.115 0.01" rpy="-1.5708 0 0"/>
    <axis xyz="0 0 1"/>
    <limit lower="0" upper="0" effort="0.0" velocity="0.0"/>
  </joint>
      
  <joint name="left_wheel_joint_5" type="revolute">
    <parent link="base_link"/>
    <child link="left_wheel5"/>
    <origin xyz="0.02 0.115 0.01" rpy="-1.5708 0 0"/>
    <axis xyz="0 0 1"/>
    <limit lower="0" upper="0" effort="0.0" velocity="0.0"/>
  </joint>
  


  
  <joint name="right_wheel_joint" type="continuous">
    <parent link="base_link"/>
    <child link="right_wheel"/>
    <origin xyz="-0.013 -0.115 0.045" rpy="1.5708 0 0"/>
    <axis xyz="0 0 -1"/>
  </joint>

      
  <joint name="right_wheel_joint_1" type="revolute">
    <parent link="base_link"/>
    <child link="right_wheel1"/>
    <origin xyz="0.110 -0.115 0.09" rpy="-1.5708 0 0"/>
    <axis xyz="0 0 1"/>
    <limit lower="0" upper="0" effort="0.0" velocity="0.0"/>
  </joint>
        
  <joint name="right_wheel_joint_2" type="revolute">
    <parent link="base_link"/>
    <child link="right_wheel2"/>
    <origin xyz="0.242 -0.115 0.045" rpy="-1.5708 0 0"/>
    <axis xyz="0 0 1"/>
    <limit lower="0" upper="0" effort="0.0" velocity="0.0"/>

  </joint>
      
  <joint name="right_wheel_joint_3" type="revolute">
    <parent link="base_link"/>
    <child link="right_wheel3"/>
    <origin xyz="0.210 -0.115 0.01" rpy="-1.5708 0 0"/>
    <axis xyz="0 0 1"/>
    <limit lower="0" upper="0" effort="0.0" velocity="0.0"/>
  </joint>
      
  <joint name="right_wheel_joint_4" type="revolute">
    <parent link="base_link"/>
    <child link="right_wheel4"/>
    <origin xyz="0.130 -0.115 0.01" rpy="-1.5708 0 0"/>
    <axis xyz="0 0 1"/>
    <limit lower="0" upper="0" effort="0.0" velocity="0.0"/>
  </joint>
        
  <joint name="right_wheel_joint_5" type="revolute">
     <parent link="base_link"/>
     <child link="right_wheel5"/>
     <origin xyz="0.02 -0.115 0.01" rpy="-1.5708 0 0"/>
     <axis xyz="0 0 1"/>
     <limit lower="0" upper="0" effort="0.0" velocity="0.0"/>
  </joint>


  

</robot> -->

